GPU:  [PhysicalDevice(name='/physical_device:GPU:0', device_type='GPU')]
Listening on port 9000
Model: "model"
_________________________________________________________________
 Layer (type)                Output Shape              Param #   
=================================================================
 input_1 (InputLayer)        [(None, 28, 28)]          0         
                                                                 
 reshape (Reshape)           (None, 28, 28, 1)         0         
                                                                 
 conv2d (Conv2D)             (None, 26, 26, 16)        160       
                                                                 
 conv2d_1 (Conv2D)           (None, 24, 24, 16)        2320      
                                                                 
 flatten (Flatten)           (None, 9216)              0         
                                                                 
 dense (Dense)               (None, 128)               1179776   
                                                                 
 dense_1 (Dense)             (None, 10)                1290      
                                                                 
=================================================================
Total params: 1,183,546
Trainable params: 1,183,546
Non-trainable params: 0
_________________________________________________________________
Epoch 1/3
2022-11-24 13:54:49.488013: E tensorflow/stream_executor/cuda/cuda_dnn.cc:389] Could not create cudnn handle: CUDNN_STATUS_INTERNAL_ERROR
2022-11-24 13:54:49.488102: W tensorflow/core/framework/op_kernel.cc:1745] OP_REQUIRES failed at conv_ops.cc:1120 : UNIMPLEMENTED: DNN library is not found.
Traceback (most recent call last):
  File "node.py", line 71, in <module>
    model.fit(train_X, train_Y, epochs=3)
  File "/usr/local/lib/python3.8/dist-packages/keras/utils/traceback_utils.py", line 67, in error_handler
    raise e.with_traceback(filtered_tb) from None
  File "/usr/local/lib/python3.8/dist-packages/tensorflow/python/eager/execute.py", line 54, in quick_execute
    tensors = pywrap_tfe.TFE_Py_Execute(ctx._handle, device_name, op_name,
tensorflow.python.framework.errors_impl.UnimplementedError: Graph execution error:

Detected at node 'model/conv2d/Conv2D' defined at (most recent call last):
    File "node.py", line 71, in <module>
      model.fit(train_X, train_Y, epochs=3)
    File "/usr/local/lib/python3.8/dist-packages/keras/utils/traceback_utils.py", line 64, in error_handler
      return fn(*args, **kwargs)
    File "/usr/local/lib/python3.8/dist-packages/keras/engine/training.py", line 1409, in fit
      tmp_logs = self.train_function(iterator)
    File "/usr/local/lib/python3.8/dist-packages/keras/engine/training.py", line 1051, in train_function
      return step_function(self, iterator)
    File "/usr/local/lib/python3.8/dist-packages/keras/engine/training.py", line 1040, in step_function
      outputs = model.distribute_strategy.run(run_step, args=(data,))
    File "/usr/local/lib/python3.8/dist-packages/keras/engine/training.py", line 1030, in run_step
      outputs = model.train_step(data)
    File "/usr/local/lib/python3.8/dist-packages/keras/engine/training.py", line 889, in train_step
      y_pred = self(x, training=True)
    File "/usr/local/lib/python3.8/dist-packages/keras/utils/traceback_utils.py", line 64, in error_handler
      return fn(*args, **kwargs)
    File "/usr/local/lib/python3.8/dist-packages/keras/engine/training.py", line 490, in __call__
      return super().__call__(*args, **kwargs)
    File "/usr/local/lib/python3.8/dist-packages/keras/utils/traceback_utils.py", line 64, in error_handler
      return fn(*args, **kwargs)
    File "/usr/local/lib/python3.8/dist-packages/keras/engine/base_layer.py", line 1014, in __call__
      outputs = call_fn(inputs, *args, **kwargs)
    File "/usr/local/lib/python3.8/dist-packages/keras/utils/traceback_utils.py", line 92, in error_handler
      return fn(*args, **kwargs)
    File "/usr/local/lib/python3.8/dist-packages/keras/engine/functional.py", line 458, in call
      return self._run_internal_graph(
    File "/usr/local/lib/python3.8/dist-packages/keras/engine/functional.py", line 596, in _run_internal_graph
      outputs = node.layer(*args, **kwargs)
    File "/usr/local/lib/python3.8/dist-packages/keras/utils/traceback_utils.py", line 64, in error_handler
      return fn(*args, **kwargs)
    File "/usr/local/lib/python3.8/dist-packages/keras/engine/base_layer.py", line 1014, in __call__
      outputs = call_fn(inputs, *args, **kwargs)
    File "/usr/local/lib/python3.8/dist-packages/keras/utils/traceback_utils.py", line 92, in error_handler
      return fn(*args, **kwargs)
    File "/usr/local/lib/python3.8/dist-packages/keras/layers/convolutional/base_conv.py", line 250, in call
      outputs = self.convolution_op(inputs, self.kernel)
    File "/usr/local/lib/python3.8/dist-packages/keras/layers/convolutional/base_conv.py", line 225, in convolution_op
      return tf.nn.convolution(
Node: 'model/conv2d/Conv2D'
DNN library is not found.
	 [[{{node model/conv2d/Conv2D}}]] [Op:__inference_train_function_802]
